Workbook

Sheet Readme
B1: AI.fred task cost measurement model
B3: This workbook turns three measured numbers per task type into a headcount and a gross margin. It is the model referred to in the measurement protocol document; fill the Capture sheet from the protocol's runs and the rest computes.
B5: How to use it
B6: 1. Open Inputs and set the demand, pricing and labour assumptions. Every cell you may edit is yellow.
B7: 2. Run the 30 tasks in the protocol. Record each task's results on one row of Capture.
B8: 3. Rollup aggregates Capture by observed tier. Nothing on Rollup is editable.
B9: 4. On Inputs, set 'Tier data source' to MEASURED once Capture has real data in it. Until then leave it on PLANNING and the model runs on your stated assumptions of 35 / 50 / 15 per cent.
B10: 5. Model shows headcount, cost per task and gross margin. The sensitivity grid at the bottom shows how margin moves with the two numbers that actually decide it.
B12: Colour convention
B13: Yellow fill with blue text: an input you set. Black text: a formula. Green text: a link to another sheet.
B15: The point of the exercise
B16: The headcount ratio is an output of this model, not an input to it. If the measured numbers give a ratio far from 1 generalist per 30 users, that is the finding, and it is better found now for a few hundred dollars of API spend than after a floor has been leased.
... B19: Token cost is modelled per task from measured input and output tokens at list prices; caching and batch discounts are not modelled and will reduce it. Supervision is a ratio of generalist headcount rather than a staffing model. Utilisation is a single figure; in reality it varies by shift and by queue arrival pattern, and above roughly 80 per cent waiting time rises sharply.

Sheet Inputs
B1: Inputs and assumptions
B2: Yellow cells are yours to set. Everything else on this sheet is derived.
B4: Demand
B5: Users (paying) | C5: 1000 | D5: Your stated pilot-scale figure
B6: Tasks per user per day | C6: 2 | D6: Your stated usage assumption
B7: Days per month | C7: 30 | D7: Service runs seven days
B8: Tasks per day (total) | C8: =C5*C6 -> 2000 | D8: Users x tasks per user per day
B10: Pricing
B11: Tier 1 price (USD per month) | C11: 20 | D11: Mass tier
B12: Tier 1 share of users | C12: 0.7
B13: Tier 2 price (USD per month) | C13: 40 | D13: Privileged tier
B14: Tier 2 share of users | C14: 0.25
B15: Tier 3 price (USD per month) | C15: 100 | D15: VIP tier
B16: Tier 3 share of users | C16: 0.05 | D16: Shares should sum to 100 per cent
B17: Blended price (USD per user per month) | C17: =C11*C12+C13*C14+C15*C16 -> 29
B18: Share check (must be 100%) | C18: =C12+C14+C16 -> 1
B19: USD to INR | C19: 88 | D19: Set to the rate you want to model
B21: Labour
B22: Generalist CTC (INR per year) | C22: 500000 | D22: Your stated 5 LPA
B23: Statutory on-cost and benefits | C23: 0.2 | D23: PF, ESI, gratuity, insurance, transport
B24: Productive minutes per head per day | C24: 390 | D24: 6.5 hours of an 8 hour shift
B25: Target utilisation | C25: 0.7 | D25: Interrupt-driven queues degrade sharply above about 80 per cent
B26: Supervisors per generalist | C26: 0.15 | D26: Team leads, QA and escalation cover
B27: Supervisor CTC (INR per year) | C27: 1200000
B29: Token prices
B30: Input tokens (USD per million) | C30: 2 | D30: Frontier list price; caching reduces this materially
B31: Output tokens (USD per million) | C31: 10
B33: Model switches
B34: Tier data source | C34: PLANNING | D34: PLANNING or MEASURED. Switch to MEASURED once Capture is filled
B35: Count hold and IVR time as human time | C35: YES | D35: YES if a worker waits on hold. NO models the case where the system dials, navigates the IVR and holds, handing the worker a connected call
B37: Planning assumptions (used when source is PLANNING)
B38: Tier | C38: Share | D38: Human minutes per task
B39: AI-only | C39: 0.35 | D39: 0
B40: Assisted | C40: 0.5 | D40: 6
B41: Human-led | C41: 0.15 | D41: 45
B42: Share check (must be 100%) | C42: =C39+C40+C41 -> 1
B43: Blended input tokens per task | C43: 120000 | D43: Planning figure until Capture is filled
B44: Blended output tokens per task | C44: 6000
B46: Other cost lines
B47: Make-good reserve (share of revenue) | C47: 0.02 | D47: Provision for putting a failed task right
...

Sheet Capture
A1: Task capture
A2: One row per task. Fill columns A to P; Q to T compute. Observed tier must be one of: AI-only, Assisted, Human-led, Bounced, Failed. Row 4 is a worked example, overwrite or delete it.
A3: Task ID | B3: Task | C3: Category | D3: Expected tier | E3: Acceptance artifact | F3: Runs attempted | G3: AI-only completions | H3: Bounced to user | I3: Failed | J3: Input tokens (avg per run) | K3: Output tokens (avg per run) | L3: Human active min | M3: Wrap min | N3: Hold / IVR min | O3: Observed tier | P3: Notes | Q3: Human min per run | R3: Human min x runs | S3: Token USD per run | T3: Token USD x runs
A4: EXAMPLE | B4: Book a table for two, Saturday 8pm, Koramangala | C4: Dining | D4: Assisted | E4: Confirmation SMS or booking reference | F4: 3 | G4: 1 | H4: 0 | I4: 0 | J4: 45000 | K4: 2500 | L4: 4 | M4: 1.5 | N4: 3 | O4: Assisted | P4: Two of three needed a call; one restaurant took an online booking | Q4: =IFERROR(N(L4)+N(M4)+IF(Inputs!$C$35="YES",N(N4),0),0) -> 8.5 | R4: =Q4*N(F4) -> 25.5 | S4: =N(J4)/1000000*Inputs!$C$30+N(K4)/1000000*Inputs!$C$31 -> 0.115 | T4: =S4*N(F4) -> 0.345
A5: T01 | B5: Restaurant shortlist for a date night, with reasons | C5: Dining | D5: AI-only | E5: Three named options with rationale | Q5: =IFERROR(N(L5)+N(M5)+IF(Inputs!$C$35="YES",N(N5),0),0) -> 0 | R5: =Q5*N(F5) -> 0 | S5: =N(J5)/1000000*Inputs!$C$30+N(K5)/1000000*Inputs!$C$31 -> 0 | T5: =S5*N(F5) -> 0
A6: T02 | B6: Compare three mobile plans and recommend one | C6: Purchase research | D6: AI-only | E6: Written recommendation with price comparison | Q6: =IFERROR(N(L6)+N(M6)+IF(Inputs!$C$35="YES",N(N6),0),0) -> 0 | R6: =Q6*N(F6) -> 0 | S6: =N(J6)/1000000*Inputs!$C$30+N(K6)/1000000*Inputs!$C$31 -> 0 | T6: =S6*N(F6) -> 0
A7: T03 | B7: Categorise last month's spending and flag anomalies | C7: Money admin | D7: AI-only | E7: Category breakdown the user confirms as correct | Q7: =IFERROR(N(L7)+N(M7)+IF(Inputs!$C$35="YES",N(N7),0),0) -> 0 | R7: =Q7*N(F7) -> 0 | S7: =N(J7)/1000000*Inputs!$C$30+N(K7)/1000000*Inputs!$C$31 -> 0 | T7: =S7*N(F7) -> 0
A8: T04 | B8: Research an air purifier under a stated budget | C8: Purchase research | D8: AI-only | E8: Shortlist with specification comparison | Q8: =IFERROR(N(L8)+N(M8)+IF(Inputs!$C$35="YES",N(N8),0),0) -> 0 | R8: =Q8*N(F8) -> 0 | S8: =N(J8)/1000000*Inputs!$C$30+N(K8)/1000000*Inputs!$C$31 -> 0 | T8: =S8*N(F8) -> 0
A9: T05 | B9: Gift options for a named occasion and relationship | C9: Shopping | D9: AI-only | E9: Three options within budget, available to order | Q9: =IFERROR(N(L9)+N(M9)+IF(Inputs!$C$35="YES",N(N9),0),0) -> 0 | R9: =Q9*N(F9) -> 0 | S9: =N(J9)/1000000*Inputs!$C$30+N(K9)/1000000*Inputs!$C$31 -> 0 | T9: =S9*N(F9) -> 0
A10: T06 | B10: Draft a complaint to an airline over a delay | C10: Correspondence | D10: AI-only | E10: Sent-ready draft with claim reference to the right address | Q10: =IFERROR(N(L10)+N(M10)+IF(Inputs!$C$35="YES",N(N10),0),0) -> 0 | R10: =Q10*N(F10) -> 0 | S10: =N(J10)/1000000*Inputs!$C$30+N(K10)/1000000*Inputs!$C$31 -> 0 | T10: =S10*N(F10) -> 0
A11: T07 | B11: Plan a Saturday outing, three variants by budget | C11: Leisure | D11: AI-only | E11: Itinerary with timings and costs | Q11: =IFERROR(N(L11)+N(M11)+IF(Inputs!$C$35="YES",N(N11),0),0) -> 0 | R11: =Q11*N(F11) -> 0 | S11: =N(J11)/1000000*Inputs!$C$30+N(K11)/1000000*Inputs!$C$31 -> 0 | T11: =S11*N(F11) -> 0
A12: T08 | B12: Visa requirement and document checklist for a destination | C12: Travel | D12: AI-only | E12: Checklist verified against the official source | Q12: =IFERROR(N(L12)+N(M12)+IF(Inputs!$C$35="YES",N(N12),0),0) -> 0 | R12: =Q12*N(F12) -> 0 | S12: =N(J12)/1000000*Inputs!$C$30+N(K12)/1000000*Inputs!$C$31 -> 0 | T12: =S12*N(F12) -> 0
A13: T09 | B13: Explain an insurance policy document and list exclusions | C13: Insurance | D13: AI-only | E13: Summary the user confirms matches the policy | Q13: =IFERROR(N(L13)+N(M13)+IF(Inputs!$C$35="YES",N(N13),0),0) -> 0 | R13: =Q13*N(F13) -> 0 | S13: =N(J13)/1000000*Inputs!$C$30+N(K13)/1000000*Inputs!$C$31 -> 0 | T13: =S13*N(F13) -> 0
A14: T10 | B14: Flight and hotel shortlist for stated dates and budget | C14: Travel | D14: AI-only | E14: Three costed options, availability confirmed | Q14: =IFERROR(N(L14)+N(M14)+IF(Inputs!$C$35="YES",N(N14),0),0) -> 0 | R14: =Q14*N(F14) -> 0 | S14: =N(J14)/1000000*Inputs!$C$30+N(K14)/1000000*Inputs!$C$31 -> 0 | T14: =S14*N(F14) -> 0
A15: T11 | B15: Reserve a table where the venue takes phone bookings only | C15: Dining | D15: Assisted | E15: Booking reference or confirmed name and time | Q15: =IFERROR(N(L15)+N(M15)+IF(Inputs!$C$35="YES",N(N15),0),0) -> 0 | R15: =Q15*N(F15) -> 0 | S15: =N(J15)/1000000*Inputs!$C$30+N(K15)/1000000*Inputs!$C$31 -> 0 | T15: =S15*N(F15) -> 0
A16: T12 | B16: Book a dentist appointment in a stated window | C16: Health admin | D16: Assisted | E16: Confirmed appointment slot | Q16: =IFERROR(N(L16)+N(M16)+IF(Inputs!$C$35="YES",N(N16),0),0) -> 0 | R16: =Q16*N(F16) -> 0 | S16: =N(J16)/1000000*Inputs!$C$30+N(K16)/1000000*Inputs!$C$31 -> 0 | T16: =S16*N(F16) -> 0
... A34: T30 | B34: Change of address across five institutions | C34: Institutional admin | D34: Human-led | E34: All five confirm the new address | Q34: =IFERROR(N(L34)+N(M34)+IF(Inputs!$C$35="YES",N(N34),0),0) -> 0 | R34: =Q34*N(F34) -> 0 | S34: =N(J34)/1000000*Inputs!$C$30+N(K34)/1000000*Inputs!$C$31 -> 0 | T34: =S34*N(F34) -> 0

Sheet Rollup
B1: Measured rollup by observed tier
B2: Computed from Capture. Nothing here is editable. Blank until Capture has data.
B4: Observed tier | C4: Runs | D4: Share of runs | E4: Human min per task | F4: Token USD per task | G4: Tasks (of 30)
B5: AI-only | C5: =SUMIFS(Capture!$F$4:$F$34,Capture!$O$4:$O$34,$B5) -> 0 | D5: =IFERROR(C5/$C$10,0) -> 0 | E5: =IFERROR(SUMIFS(Capture!$R$4:$R$34,Capture!$O$4:$O$34,$B5)/C5,0) -> 0 | F5: =IFERROR(SUMIFS(Capture!$T$4:$T$34,Capture!$O$4:$O$34,$B5)/C5,0) -> 0 | G5: =COUNTIFS(Capture!$O$4:$O$34,$B5) -> 0
B6: Assisted | C6: =SUMIFS(Capture!$F$4:$F$34,Capture!$O$4:$O$34,$B6) -> 3 | D6: =IFERROR(C6/$C$10,0) -> 1 | E6: =IFERROR(SUMIFS(Capture!$R$4:$R$34,Capture!$O$4:$O$34,$B6)/C6,0) -> 8.5 | F6: =IFERROR(SUMIFS(Capture!$T$4:$T$34,Capture!$O$4:$O$34,$B6)/C6,0) -> 0.115 | G6: =COUNTIFS(Capture!$O$4:$O$34,$B6) -> 1
B7: Human-led | C7: =SUMIFS(Capture!$F$4:$F$34,Capture!$O$4:$O$34,$B7) -> 0 | D7: =IFERROR(C7/$C$10,0) -> 0 | E7: =IFERROR(SUMIFS(Capture!$R$4:$R$34,Capture!$O$4:$O$34,$B7)/C7,0) -> 0 | F7: =IFERROR(SUMIFS(Capture!$T$4:$T$34,Capture!$O$4:$O$34,$B7)/C7,0) -> 0 | G7: =COUNTIFS(Capture!$O$4:$O$34,$B7) -> 0
B8: Bounced | C8: =SUMIFS(Capture!$F$4:$F$34,Capture!$O$4:$O$34,$B8) -> 0 | D8: =IFERROR(C8/$C$10,0) -> 0 | E8: =IFERROR(SUMIFS(Capture!$R$4:$R$34,Capture!$O$4:$O$34,$B8)/C8,0) -> 0 | F8: =IFERROR(SUMIFS(Capture!$T$4:$T$34,Capture!$O$4:$O$34,$B8)/C8,0) -> 0 | G8: =COUNTIFS(Capture!$O$4:$O$34,$B8) -> 0
B9: Failed | C9: =SUMIFS(Capture!$F$4:$F$34,Capture!$O$4:$O$34,$B9) -> 0 | D9: =IFERROR(C9/$C$10,0) -> 0 | E9: =IFERROR(SUMIFS(Capture!$R$4:$R$34,Capture!$O$4:$O$34,$B9)/C9,0) -> 0 | F9: =IFERROR(SUMIFS(Capture!$T$4:$T$34,Capture!$O$4:$O$34,$B9)/C9,0) -> 0 | G9: =COUNTIFS(Capture!$O$4:$O$34,$B9) -> 0
B10: Total | C10: =SUM(C5:C9) -> 3 | D10: =SUM(D5:D9) -> 1 | G10: =SUM(G5:G9) -> 1
B12: Derived checks
B13: AI-only completion rate (all runs) | C13: =IFERROR(SUM(Capture!$G$4:$G$34)/SUM(Capture!$F$4:$F$34),0) -> 0.33333333
B14: Bounce rate (share of runs) | C14: =IFERROR(C8/$C$10,0) -> 0
B15: Blended human minutes per task | C15: =IFERROR(SUMPRODUCT(C5:C9,E5:E9)/$C$10,0) -> 8.5
B16: Blended token cost per task (USD) | C16: =IFERROR(SUMPRODUCT(C5:C9,F5:F9)/$C$10,0) -> 0.115

Sheet Model
B1: Headcount and margin
B2: Everything here is computed. Change Inputs, or fill Capture and switch the source to MEASURED.
B4: Task mix in force
B5: Source | C5: =Inputs!C34 -> PLANNING
B6: AI-only share | C6: =IF(Inputs!$C$34="MEASURED",Rollup!D5,Inputs!C39) -> 0.35
B7: Assisted share | C7: =IF(Inputs!$C$34="MEASURED",Rollup!D6,Inputs!C40) -> 0.5
B8: Human-led share | C8: =IF(Inputs!$C$34="MEASURED",Rollup!D7,Inputs!C41) -> 0.15
B9: Bounced share | C9: =IF(Inputs!$C$34="MEASURED",Rollup!D8,0) -> 0 | D9: Little labour, but it is the promise that is spent
B10: Failed share | C10: =IF(Inputs!$C$34="MEASURED",Rollup!D9,0) -> 0
B11: AI-only human minutes | C11: =IF(Inputs!$C$34="MEASURED",Rollup!E5,Inputs!D39) -> 0
B12: Assisted human minutes | C12: =IF(Inputs!$C$34="MEASURED",Rollup!E6,Inputs!D40) -> 6
B13: Human-led human minutes | C13: =IF(Inputs!$C$34="MEASURED",Rollup!E7,Inputs!D41) -> 45
B14: Blended human minutes per task | C14: =C6*C11+C7*C12+C8*C13 -> 9.75 | D14: The single number that sets headcount
B15: Blended token cost per task (USD) | C15: =IF(Inputs!$C$34="MEASURED",Rollup!C16,Inputs!C43/1000000*Inputs!C30+Inputs!C44/1000000*Inputs!C31) -> 0.3
B17: Volume and labour
B18: Tasks per day | C18: =Inputs!C8 -> 2000
B19: Human minutes required per day | C19: =C18*C14 -> 19500
B20: Effective minutes per head per day | C20: =Inputs!C24*Inputs!C25 -> 273 | D20: Productive minutes x utilisation
B21: Generalists required | C21: =IFERROR(ROUNDUP(C19/C20,0),0) -> 72
B22: Supervisors required | C22: =IFERROR(ROUNDUP(C21*Inputs!C26,0),0) -> 11
B23: Total floor headcount | C23: =C21+C22 -> 83
B24: Users per generalist | C24: =IFERROR(Inputs!C5/C21,0) -> 13.888889 | D24: Compare with the 1:30 assumption
B26: Monthly profit and loss (INR)
B27: Revenue | C27: =Inputs!C5*Inputs!C17*Inputs!C19 -> 2552000
B28: Generalist cost | C28: =C21*Inputs!C22*(1+Inputs!C23)/12 -> 3600000
B29: Supervisor cost | C29: =C22*Inputs!C27*(1+Inputs!C23)/12 -> 1320000
B30: Token cost | C30: =C18*Inputs!C7*C15*Inputs!C19 -> 1584000
B31: Make-good reserve | C31: =C27*Inputs!C47 -> 51040
B32: Fixed overhead | C32: =Inputs!C48 -> 150000
B33: Total cost | C33: =SUM(C28:C32) -> 6705040
B34: Contribution | C34: =C27-C33 -> -4153040
B35: Gross margin | C35: =IFERROR(C34/C27,0) -> -1.6273668
B37: Per task
B38: Revenue per task (INR) | C38: =IFERROR(C27/(C18*Inputs!C7),0) -> 42.533333
B39: Labour cost per task (INR) | C39: =IFERROR((C28+C29)/(C18*Inputs!C7),0) -> 82
B40: Token cost per task (INR) | C40: =C15*Inputs!C19 -> 26.4
B41: Total cost per task (INR) | C41: =IFERROR(C33/(C18*Inputs!C7),0) -> 111.75067
B43: Sensitivity: gross margin by AI-only share and human-led handling time
B44: Rows: minutes per human-led task. Columns: AI-only share. Assisted minutes and human-led share held at the values above.
B45: Human-led min \ AI-only share | C45: 0.2 | D45: 0.25 | E45: 0.3 | F45: 0.35 | G45: 0.4 | H45: 0.5
...

Sheet Trajectory
B1: 36 month trajectory
B2: Simulates three improvements at once: AI takes a rising share of tasks, humans get faster on what is left, and users grow. Yellow cells are drivers. The monthly grid starts at row 35.
B4: Growth
B5: Starting users (month 1) | C5: 250
B6: Net monthly user growth | C6: 0.12 | E6: Net of churn
B7: User ceiling | C7: 25000 | E7: Growth flattens here
B8: Tasks per user per day | C8: 2 | E8: Held constant across the run
B10: AI efficiency
B11: AI-only share, month 1 | C11: 0.45
B12: AI-only share ceiling | C12: 0.75 | E12: Where automation saturates
B13: Half life of the gap (months) | C13: 12 | E13: Months to close half the distance to the ceiling
B14: Token cost per task, month 1 (USD) | C14: 0.3
B15: Monthly decline in token cost | C15: 0.06 | E15: 6 per cent a month is roughly halving each year
B17: Human efficiency
B18: Assisted minutes, month 1 | C18: 6
B19: Assisted minutes floor | C19: 2.5 | E19: Where practice stops paying
B20: Human-led minutes, month 1 | C20: 45
B21: Human-led minutes floor | C21: 25
B22: Half life of the gap (months) | C22: 12 | E22: Learning curve speed
B23: Human-led share, month 1 | C23: 0.05
B24: Human-led share floor | C24: 0.05 | E24: Set equal to month 1 to hold it constant
B26: Costs and price
B27: Blended price per user (USD per month) | C27: 29 | E27: Change to test pricing
B28: Annual wage inflation | C28: 0.09 | E28: Applied to generalists and supervisors
B29: Engineering and G and A, month 1 (INR) | C29: 2000000 | E29: Founders, engineers, counsel, marketing
B30: Monthly growth in that line | C30: 0.02
B31: Seat cost per floor head per month (INR) | C31: 3000 | E31: Space, connectivity, device
B33: Monthly grid
B35: Month | C35: 1 | D35: 2 | E35: 3 | F35: 4 | G35: 5 | H35: 6 | I35: 7 | J35: 8 | K35: 9 | L35: 10 | M35: 11 | N35: 12 | O35: 13 | P35: 14 | Q35: 15 | R35: 16 | S35: 17 | T35: 18 | U35: 19 | V35: 20 | W35: 21 | X35: 22 | Y35: 23 | Z35: 24 | AA35: 25 | AB35: 26 | AC35: 27 | AD35: 28 | AE35: 29 | AF35: 30 | AG35: 31 | AH35: 32 | AI35: 33 | AJ35: 34 | AK35: 35 | AL35: 36
B36: Users | C36: =MIN($C$7,$C$5*(1+$C$6)^0) -> 250 | D36: =MIN($C$7,$C$5*(1+$C$6)^1) -> 280 | E36: =MIN($C$7,$C$5*(1+$C$6)^2) -> 313.6 | F36: =MIN($C$7,$C$5*(1+$C$6)^3) -> 351.232 | G36: =MIN($C$7,$C$5*(1+$C$6)^4) -> 393.37984 | H36: =MIN($C$7,$C$5*(1+$C$6)^5) -> 440.58542 | I36: =MIN($C$7,$C$5*(1+$C$6)^6) -> 493.45567 | J36: =MIN($C$7,$C$5*(1+$C$6)^7) -> 552.67035 | K36: =MIN($C$7,$C$5*(1+$C$6)^8) -> 618.99079 | L36: =MIN($C$7,$C$5*(1+$C$6)^9) -> 693.26969 | M36: =MIN($C$7,$C$5*(1+$C$6)^10) -> 776.46205 | N36: =MIN($C$7,$C$5*(1+$C$6)^11) -> 869.6375 | O36: =MIN($C$7,$C$5*(1+$C$6)^12) -> 973.994 | P36: =MIN($C$7,$C$5*(1+$C$6)^13) -> 1090.8733 | Q36: =MIN($C$7,$C$5*(1+$C$6)^14) -> 1221.7781 | R36: =MIN($C$7,$C$5*(1+$C$6)^15) -> 1368.3914 | S36: =MIN($C$7,$C$5*(1+$C$6)^16) -> 1532.5984 | T36: =MIN($C$7,$C$5*(1+$C$6)^17) -> 1716.5102 | U36: =MIN($C$7,$C$5*(1+$C$6)^18) -> 1922.4914 | V36: =MIN($C$7,$C$5*(1+$C$6)^19) -> 2153.1904 | W36: =MIN($C$7,$C$5*(1+$C$6)^20) -> 2411.5733 | X36: =MIN($C$7,$C$5*(1+$C$6)^21) -> 2700.9621 | Y36: =MIN($C$7,$C$5*(1+$C$6)^22) -> 3025.0775 | Z36: =MIN($C$7,$C$5*(1+$C$6)^23) -> 3388.0868 | AA36: =MIN($C$7,$C$5*(1+$C$6)^24) -> 3794.6572 | AB36: =MIN($C$7,$C$5*(1+$C$6)^25) -> 4250.0161 | AC36: =MIN($C$7,$C$5*(1+$C$6)^26) -> 4760.018 | AD36: =MIN($C$7,$C$5*(1+$C$6)^27) -> 5331.2202 | AE36: =MIN($C$7,$C$5*(1+$C$6)^28) -> 5970.9666 | AF36: =MIN($C$7,$C$5*(1+$C$6)^29) -> 6687.4826 | AG36: =MIN($C$7,$C$5*(1+$C$6)^30) -> 7489.9805 | AH36: =MIN($C$7,$C$5*(1+$C$6)^31) -> 8388.7782 | AI36: =MIN($C$7,$C$5*(1+$C$6)^32) -> 9395.4316 | AJ36: =MIN($C$7,$C$5*(1+$C$6)^33) -> 10522.883 | AK36: =MIN($C$7,$C$5*(1+$C$6)^34) -> 11785.629 | AL36: =MIN($C$7,$C$5*(1+$C$6)^35) -> 13199.905
B37: Tasks per day | C37: =C36*$C$8 -> 500 | D37: =D36*$C$8 -> 560 | E37: =E36*$C$8 -> 627.2 | F37: =F36*$C$8 -> 702.464 | G37: =G36*$C$8 -> 786.75968 | H37: =H36*$C$8 -> 881.17084 | I37: =I36*$C$8 -> 986.91134 | J37: =J36*$C$8 -> 1105.3407 | ... AL37: =AL36*$C$8 -> 26399.81
B38: AI-only share | C38: =$C$12-($C$12-$C$11)*EXP(-LN(2)/$C$13*0) -> 0.45 | D38: =$C$12-($C$12-$C$11)*EXP(-LN(2)/$C$13*1) -> 0.46683771 | E38: =$C$12-($C$12-$C$11)*EXP(-LN(2)/$C$13*2) -> 0.48273038 | F38: =$C$12-($C$12-$C$11)*EXP(-LN(2)/$C$13*3) -> 0.49773108 | G38: =$C$12-($C$12-$C$11)*EXP(-LN(2)/$C$13*4) -> 0.51188984 | H38: =$C$12-($C$12-$C$11)*EXP(-LN(2)/$C$13*5) -> 0.52525394 | I38: =$C$12-($C$12-$C$11)*EXP(-LN(2)/$C$13*6) -> 0.53786797 | J38: =$C$12-($C$12-$C$11)*EXP(-LN(2)/$C$13*7) -> 0.54977402 | K38: =$C$12-($C$12-$C$11)*EXP(-LN(2)/$C$13*8) -> 0.56101184 | L38: =$C$12-($C$12-$C$11)*EXP(-LN(2)/$C$13*9) -> 0.57161893 | M38: =$C$12-($C$12-$C$11)*EXP(-LN(2)/$C$13*10) -> 0.58163069 | N38: =$C$12-($C$12-$C$11)*EXP(-LN(2)/$C$13*11) -> 0.59108054 | O38: =$C$12-($C$12-$C$11)*EXP(-LN(2)/$C$13*12) -> 0.6 | P38: =$C$12-($C$12-$C$11)*EXP(-LN(2)/$C$13*13) -> 0.60841885 | Q38: =$C$12-($C$12-$C$11)*EXP(-LN(2)/$C$13*14) -> 0.61636519 | R38: =$C$12-($C$12-$C$11)*EXP(-LN(2)/$C$13*15) -> 0.62386554 | S38: =$C$12-($C$12-$C$11)*EXP(-LN(2)/$C$13*16) -> 0.63094492 | T38: =$C$12-($C$12-$C$11)*EXP(-LN(2)/$C$13*17) -> 0.63762697 | U38: =$C$12-($C$12-$C$11)*EXP(-LN(2)/$C$13*18) -> 0.64393398 | V38: =$C$12-($C$12-$C$11)*EXP(-LN(2)/$C$13*19) -> 0.64988701 | W38: =$C$12-($C$12-$C$11)*EXP(-LN(2)/$C$13*20) -> 0.65550592 | X38: =$C$12-($C$12-$C$11)*EXP(-LN(2)/$C$13*21) -> 0.66080947 | Y38: =$C$12-($C$12-$C$11)*EXP(-LN(2)/$C$13*22) -> 0.66581535 | Z38: =$C$12-($C$12-$C$11)*EXP(-LN(2)/$C$13*23) -> 0.67054027 | AA38: =$C$12-($C$12-$C$11)*EXP(-LN(2)/$C$13*24) -> 0.675 | AB38: =$C$12-($C$12-$C$11)*EXP(-LN(2)/$C$13*25) -> 0.67920943 | AC38: =$C$12-($C$12-$C$11)*EXP(-LN(2)/$C$13*26) -> 0.6831826 | AD38: =$C$12-($C$12-$C$11)*EXP(-LN(2)/$C$13*27) -> 0.68693277 | AE38: =$C$12-($C$12-$C$11)*EXP(-LN(2)/$C$13*28) -> 0.69047246 | AF38: =$C$12-($C$12-$C$11)*EXP(-LN(2)/$C$13*29) -> 0.69381348 | AG38: =$C$12-($C$12-$C$11)*EXP(-LN(2)/$C$13*30) -> 0.69696699 | AH38: =$C$12-($C$12-$C$11)*EXP(-LN(2)/$C$13*31) -> 0.69994351 | AI38: =$C$12-($C$12-$C$11)*EXP(-LN(2)/$C$13*32) -> 0.70275296 | AJ38: =$C$12-($C$12-$C$11)*EXP(-LN(2)/$C$13*33) -> 0.70540473 | AK38: =$C$12-($C$12-$C$11)*EXP(-LN(2)/$C$13*34) -> 0.70790767 | AL38: =$C$12-($C$12-$C$11)*EXP(-LN(2)/$C$13*35) -> 0.71027013
B39: Human-led share | C39: =$C$24+($C$23-$C$24)*EXP(-LN(2)/$C$22*0) -> 0.05 | D39: =$C$24+($C$23-$C$24)*EXP(-LN(2)/$C$22*1) -> 0.05 | E39: =$C$24+($C$23-$C$24)*EXP(-LN(2)/$C$22*2) -> 0.05 | F39: =$C$24+($C$23-$C$24)*EXP(-LN(2)/$C$22*3) -> 0.05 | G39: =$C$24+($C$23-$C$24)*EXP(-LN(2)/$C$22*4) -> 0.05 | H39: =$C$24+($C$23-$C$24)*EXP(-LN(2)/$C$22*5) -> 0.05 | I39: =$C$24+($C$23-$C$24)*EXP(-LN(2)/$C$22*6) -> 0.05 | J39: =$C$24+($C$23-$C$24)*EXP(-LN(2)/$C$22*7) -> 0.05 | K39: =$C$24+($C$23-$C$24)*EXP(-LN(2)/$C$22*8) -> 0.05 | L39: =$C$24+($C$23-$C$24)*EXP(-LN(2)/$C$22*9) -> 0.05 | M39: =$C$24+($C$23-$C$24)*EXP(-LN(2)/$C$22*10) -> 0.05 | N39: =$C$24+($C$23-$C$24)*EXP(-LN(2)/$C$22*11) -> 0.05 | O39: =$C$24+($C$23-$C$24)*EXP(-LN(2)/$C$22*12) -> 0.05 | P39: =$C$24+($C$23-$C$24)*EXP(-LN(2)/$C$22*13) -> 0.05 | Q39: =$C$24+($C$23-$C$24)*EXP(-LN(2)/$C$22*14) -> 0.05 | R39: =$C$24+($C$23-$C$24)*EXP(-LN(2)/$C$22*15) -> 0.05 | S39: =$C$24+($C$23-$C$24)*EXP(-LN(2)/$C$22*16) -> 0.05 | T39: =$C$24+($C$23-$C$24)*EXP(-LN(2)/$C$22*17) -> 0.05 | U39: =$C$24+($C$23-$C$24)*EXP(-LN(2)/$C$22*18) -> 0.05 | V39: =$C$24+($C$23-$C$24)*EXP(-LN(2)/$C$22*19) -> 0.05 | W39: =$C$24+($C$23-$C$24)*EXP(-LN(2)/$C$22*20) -> 0.05 | X39: =$C$24+($C$23-$C$24)*EXP(-LN(2)/$C$22*21) -> 0.05 | Y39: =$C$24+($C$23-$C$24)*EXP(-LN(2)/$C$22*22) -> 0.05 | Z39: =$C$24+($C$23-$C$24)*EXP(-LN(2)/$C$22*23) -> 0.05 | AA39: =$C$24+($C$23-$C$24)*EXP(-LN(2)/$C$22*24) -> 0.05 | AB39: =$C$24+($C$23-$C$24)*EXP(-LN(2)/$C$22*25) -> 0.05 | AC39: =$C$24+($C$23-$C$24)*EXP(-LN(2)/$C$22*26) -> 0.05 | AD39: =$C$24+($C$23-$C$24)*EXP(-LN(2)/$C$22*27) -> 0.05 | AE39: =$C$24+($C$23-$C$24)*EXP(-LN(2)/$C$22*28) -> 0.05 | AF39: =$C$24+($C$23-$C$24)*EXP(-LN(2)/$C$22*29) -> 0.05 | AG39: =$C$24+($C$23-$C$24)*EXP(-LN(2)/$C$22*30) -> 0.05 | AH39: =$C$24+($C$23-$C$24)*EXP(-LN(2)/$C$22*31) -> 0.05 | AI39: =$C$24+($C$23-$C$24)*EXP(-LN(2)/$C$22*32) -> 0.05 | AJ39: =$C$24+($C$23-$C$24)*EXP(-LN(2)/$C$22*33) -> 0.05 | AK39: =$C$24+($C$23-$C$24)*EXP(-LN(2)/$C$22*34) -> 0.05 | AL39: =$C$24+($C$23-$C$24)*EXP(-LN(2)/$C$22*35) -> 0.05
B40: Assisted share | C40: =MAX(0,1-C38-C39) -> 0.5 | D40: =MAX(0,1-D38-D39) -> 0.48316229 | E40: =MAX(0,1-E38-E39) -> 0.46726962 | F40: =MAX(0,1-F38-F39) -> 0.45226892 | G40: =MAX(0,1-G38-G39) -> 0.43811016 | H40: =MAX(0,1-H38-H39) -> 0.42474606 | I40: =MAX(0,1-I38-I39) -> 0.41213203 | J40: =MAX(0,1-J38-J39) -> 0.40022598 | ... AL40: =MAX(0,1-AL38-AL39) -> 0.23972987
B41: Assisted minutes | C41: =$C$19+($C$18-$C$19)*EXP(-LN(2)/$C$22*0) -> 6 | D41: =$C$19+($C$18-$C$19)*EXP(-LN(2)/$C$22*1) -> 5.8035601 | E41: =$C$19+($C$18-$C$19)*EXP(-LN(2)/$C$22*2) -> 5.6181455 | F41: =$C$19+($C$18-$C$19)*EXP(-LN(2)/$C$22*3) -> 5.4431375 | G41: =$C$19+($C$18-$C$19)*EXP(-LN(2)/$C$22*4) -> 5.2779518 | H41: =$C$19+($C$18-$C$19)*EXP(-LN(2)/$C$22*5) -> 5.1220374 | I41: =$C$19+($C$18-$C$19)*EXP(-LN(2)/$C$22*6) -> 4.9748737 | J41: =$C$19+($C$18-$C$19)*EXP(-LN(2)/$C$22*7) -> 4.8359697 | K41: =$C$19+($C$18-$C$19)*EXP(-LN(2)/$C$22*8) -> 4.7048618 | L41: =$C$19+($C$18-$C$19)*EXP(-LN(2)/$C$22*9) -> 4.5811125 | M41: =$C$19+($C$18-$C$19)*EXP(-LN(2)/$C$22*10) -> 4.4643086 | N41: =$C$19+($C$18-$C$19)*EXP(-LN(2)/$C$22*11) -> 4.3540604 | O41: =$C$19+($C$18-$C$19)*EXP(-LN(2)/$C$22*12) -> 4.25 | P41: =$C$19+($C$18-$C$19)*EXP(-LN(2)/$C$22*13) -> 4.15178 | Q41: =$C$19+($C$18-$C$19)*EXP(-LN(2)/$C$22*14) -> 4.0590728 | R41: =$C$19+($C$18-$C$19)*EXP(-LN(2)/$C$22*15) -> 3.9715687 | S41: =$C$19+($C$18-$C$19)*EXP(-LN(2)/$C$22*16) -> 3.8889759 | T41: =$C$19+($C$18-$C$19)*EXP(-LN(2)/$C$22*17) -> 3.8110187 | U41: =$C$19+($C$18-$C$19)*EXP(-LN(2)/$C$22*18) -> 3.7374369 | V41: =$C$19+($C$18-$C$19)*EXP(-LN(2)/$C$22*19) -> 3.6679849 | W41: =$C$19+($C$18-$C$19)*EXP(-LN(2)/$C$22*20) -> 3.6024309 | X41: =$C$19+($C$18-$C$19)*EXP(-LN(2)/$C$22*21) -> 3.5405562 | Y41: =$C$19+($C$18-$C$19)*EXP(-LN(2)/$C$22*22) -> 3.4821543 | Z41: =$C$19+($C$18-$C$19)*EXP(-LN(2)/$C$22*23) -> 3.4270302 | AA41: =$C$19+($C$18-$C$19)*EXP(-LN(2)/$C$22*24) -> 3.375 | AB41: =$C$19+($C$18-$C$19)*EXP(-LN(2)/$C$22*25) -> 3.32589 | AC41: =$C$19+($C$18-$C$19)*EXP(-LN(2)/$C$22*26) -> 3.2795364 | AD41: =$C$19+($C$18-$C$19)*EXP(-LN(2)/$C$22*27) -> 3.2357844 | AE41: =$C$19+($C$18-$C$19)*EXP(-LN(2)/$C$22*28) -> 3.194488 | AF41: =$C$19+($C$18-$C$19)*EXP(-LN(2)/$C$22*29) -> 3.1555093 | AG41: =$C$19+($C$18-$C$19)*EXP(-LN(2)/$C$22*30) -> 3.1187184 | AH41: =$C$19+($C$18-$C$19)*EXP(-LN(2)/$C$22*31) -> 3.0839924 | AI41: =$C$19+($C$18-$C$19)*EXP(-LN(2)/$C$22*32) -> 3.0512155 | AJ41: =$C$19+($C$18-$C$19)*EXP(-LN(2)/$C$22*33) -> 3.0202781 | AK41: =$C$19+($C$18-$C$19)*EXP(-LN(2)/$C$22*34) -> 2.9910771 | AL41: =$C$19+($C$18-$C$19)*EXP(-LN(2)/$C$22*35) -> 2.9635151
B42: Human-led minutes | C42: =$C$21+($C$20-$C$21)*EXP(-LN(2)/$C$22*0) -> 45 | D42: =$C$21+($C$20-$C$21)*EXP(-LN(2)/$C$22*1) -> 43.877486 | E42: =$C$21+($C$20-$C$21)*EXP(-LN(2)/$C$22*2) -> 42.817974 | F42: =$C$21+($C$20-$C$21)*EXP(-LN(2)/$C$22*3) -> 41.817928 | G42: =$C$21+($C$20-$C$21)*EXP(-LN(2)/$C$22*4) -> 40.874011 | H42: =$C$21+($C$20-$C$21)*EXP(-LN(2)/$C$22*5) -> 39.983071 | I42: =$C$21+($C$20-$C$21)*EXP(-LN(2)/$C$22*6) -> 39.142136 | J42: =$C$21+($C$20-$C$21)*EXP(-LN(2)/$C$22*7) -> 38.348399 | K42: =$C$21+($C$20-$C$21)*EXP(-LN(2)/$C$22*8) -> 37.59921 | L42: =$C$21+($C$20-$C$21)*EXP(-LN(2)/$C$22*9) -> 36.892071 | M42: =$C$21+($C$20-$C$21)*EXP(-LN(2)/$C$22*10) -> 36.22462 | N42: =$C$21+($C$20-$C$21)*EXP(-LN(2)/$C$22*11) -> 35.594631 | O42: =$C$21+($C$20-$C$21)*EXP(-LN(2)/$C$22*12) -> 35 | P42: =$C$21+($C$20-$C$21)*EXP(-LN(2)/$C$22*13) -> 34.438743 | Q42: =$C$21+($C$20-$C$21)*EXP(-LN(2)/$C$22*14) -> 33.908987 | R42: =$C$21+($C$20-$C$21)*EXP(-LN(2)/$C$22*15) -> 33.408964 | S42: =$C$21+($C$20-$C$21)*EXP(-LN(2)/$C$22*16) -> 32.937005 | T42: =$C$21+($C$20-$C$21)*EXP(-LN(2)/$C$22*17) -> 32.491535 | U42: =$C$21+($C$20-$C$21)*EXP(-LN(2)/$C$22*18) -> 32.071068 | V42: =$C$21+($C$20-$C$21)*EXP(-LN(2)/$C$22*19) -> 31.674199 | W42: =$C$21+($C$20-$C$21)*EXP(-LN(2)/$C$22*20) -> 31.299605 | X42: =$C$21+($C$20-$C$21)*EXP(-LN(2)/$C$22*21) -> 30.946036 | Y42: =$C$21+($C$20-$C$21)*EXP(-LN(2)/$C$22*22) -> 30.61231 | Z42: =$C$21+($C$20-$C$21)*EXP(-LN(2)/$C$22*23) -> 30.297315 | AA42: =$C$21+($C$20-$C$21)*EXP(-LN(2)/$C$22*24) -> 30 | AB42: =$C$21+($C$20-$C$21)*EXP(-LN(2)/$C$22*25) -> 29.719372 | AC42: =$C$21+($C$20-$C$21)*EXP(-LN(2)/$C$22*26) -> 29.454494 | AD42: =$C$21+($C$20-$C$21)*EXP(-LN(2)/$C$22*27) -> 29.204482 | AE42: =$C$21+($C$20-$C$21)*EXP(-LN(2)/$C$22*28) -> 28.968503 | AF42: =$C$21+($C$20-$C$21)*EXP(-LN(2)/$C$22*29) -> 28.745768 | AG42: =$C$21+($C$20-$C$21)*EXP(-LN(2)/$C$22*30) -> 28.535534 | AH42: =$C$21+($C$20-$C$21)*EXP(-LN(2)/$C$22*31) -> 28.3371 | AI42: =$C$21+($C$20-$C$21)*EXP(-LN(2)/$C$22*32) -> 28.149803 | AJ42: =$C$21+($C$20-$C$21)*EXP(-LN(2)/$C$22*33) -> 27.973018 | AK42: =$C$21+($C$20-$C$21)*EXP(-LN(2)/$C$22*34) -> 27.806155 | AL42: =$C$21+($C$20-$C$21)*EXP(-LN(2)/$C$22*35) -> 27.648658
B43: Blended human minutes per task | C43: =C40*C41+C39*C42 -> 5.25 | D43: =D40*D41+D39*D42 -> 4.9979357 | E43: =E40*E41+E39*E42 -> 4.7660874 | F43: =F40*F41+F39*F42 -> 4.5526583 | G43: =G40*G41+G39*G42 -> 4.3560248 | H43: =H40*H41+H39*H42 -> 4.1747187 | I43: =I40*I41+I39*I42 -> 4.0074116 | J43: =J40*J41+J39*J42 -> 3.8529006 | ... AL43: =AL40*AL41+AL39*AL42 -> 2.092876
B44: Human minutes per day | C44: =C37*C43 -> 2625 | D44: =D37*D43 -> 2798.844 | E44: =E37*E43 -> 2989.29 | F44: =F37*F43 -> 3198.0786 | G44: =G37*G43 -> 3427.1447 | H44: =H37*H43 -> 3678.6404 | I44: =I37*I43 -> 3954.96 | J44: =J37*J43 -> 4258.7679 | ... AL44: =AL37*AL43 -> 55251.527
B45: Generalists | C45: =ROUNDUP(C44/(Inputs!$C$24*Inputs!$C$25),0) -> 10 | D45: =ROUNDUP(D44/(Inputs!$C$24*Inputs!$C$25),0) -> 11 | E45: =ROUNDUP(E44/(Inputs!$C$24*Inputs!$C$25),0) -> 11 | F45: =ROUNDUP(F44/(Inputs!$C$24*Inputs!$C$25),0) -> 12 | G45: =ROUNDUP(G44/(Inputs!$C$24*Inputs!$C$25),0) -> 13 | H45: =ROUNDUP(H44/(Inputs!$C$24*Inputs!$C$25),0) -> 14 | I45: =ROUNDUP(I44/(Inputs!$C$24*Inputs!$C$25),0) -> 15 | J45: =ROUNDUP(J44/(Inputs!$C$24*Inputs!$C$25),0) -> 16 | ... AL45: =ROUNDUP(AL44/(Inputs!$C$24*Inputs!$C$25),0) -> 203
B46: Supervisors | C46: =ROUNDUP(C45*Inputs!$C$26,0) -> 2 | D46: =ROUNDUP(D45*Inputs!$C$26,0) -> 2 | E46: =ROUNDUP(E45*Inputs!$C$26,0) -> 2 | F46: =ROUNDUP(F45*Inputs!$C$26,0) -> 2 | G46: =ROUNDUP(G45*Inputs!$C$26,0) -> 2 | H46: =ROUNDUP(H45*Inputs!$C$26,0) -> 3 | I46: =ROUNDUP(I45*Inputs!$C$26,0) -> 3 | J46: =ROUNDUP(J45*Inputs!$C$26,0) -> 3 | ... AL46: =ROUNDUP(AL45*Inputs!$C$26,0) -> 31
...
